<?xml version='1.0'?>
<sdf version='1.4'>
  <model name="fyp_robot">
  <static>false</static>
  <!-- Add the rectangular base -->
  <link name='chassis'>
   <pose>0 0 0.21 0 0 0</pose> <!-- 0.5+0.06(dist of floor to bottom of vehicle)-->

   <collision name='collision'>
     <geometry>
      <box>
       <size>.5 .5 0.3</size> <!-- 0.5 x 0.5 x 1.0 meters in size-->
      </box>
     </geometry>
    </collision>

    <visual name='visual'>
     <geometry>
      <box>
       <size>.5 .5 0.3</size> <!-- 0.5 x 0.5 x 1.0 meters in size-->
      </box>
     </geometry>
<!-- add a caster to the robot -->
<!--The caster is a sphere with no friction. This kind of caster is better than adding a wheel with a joint since it places fewer constraints on the physics engine-->
    </visual>
    <collision name='caster_collision'>
      <pose>-0.19 0 -0.15 0 0 0</pose> <!-- (0.5/2) -/+ (radius/2)-->
      <geometry>
          <sphere>
          <radius>.06</radius>
         </sphere>
        </geometry>

        <surface>
         <friction>
           <ode>
            <mu>0</mu>
            <mu2>0</mu2>
            <slip1>1.0</slip1>
            <slip2>1.0</slip2>
           </ode>
          </friction>
         </surface>
        </collision>

        <visual name='caster_visual'>
          <pose>-0.19 0 -0.15 0 0 0</pose>
          <geometry>
            <sphere>
              <radius>.06</radius>
            </sphere>
           </geometry>
         </visual>

    <collision name='caster_front_left_collision'>
      <pose>0.19 0.19 -0.15 0 0 0</pose> <!-- (0.5/2) -/+ (radius/2)-->
      <geometry>
          <sphere>
          <radius>.06</radius>
         </sphere>
        </geometry>

        <surface>
         <friction>
           <ode>
            <mu>0</mu>
            <mu2>0</mu2>
            <slip1>1.0</slip1>
            <slip2>1.0</slip2>
           </ode>
          </friction>
         </surface>
        </collision>

        <visual name='caster_front_left_visual'>
          <pose>0.19 0.19 -0.15 0 0 0</pose> <!-- (0.5/2) - (radius/2)-->
          <geometry>
            <sphere>
              <radius>.06</radius>
            </sphere>
           </geometry>
         </visual>

    <collision name='caster_front_right_collision'>
      <pose>0.19 -0.19 -0.15 0 0 0</pose> <!-- (0.5/2) -/+ (radius/2)-->
      <geometry>
          <sphere>
          <radius>.06</radius>
         </sphere>
        </geometry>

        <surface>
         <friction>
           <ode>
            <mu>0</mu>
            <mu2>0</mu2>
            <slip1>1.0</slip1>
            <slip2>1.0</slip2>
           </ode>
          </friction>
         </surface>
        </collision>

        <visual name='caster_front_right_visual'>
          <pose>0.19 -0.19 -0.15 0 0 0</pose>
          <geometry>
            <sphere>
              <radius>.06</radius>
            </sphere>
           </geometry>
         </visual>
<!-- add a left wheel to the robot -->
   </link>
   <link name="left_wheel">
     <pose>0 0.225 0.1 0 1.5707 1.5707</pose>
     <collision name="collision">
       <geometry>
         <cylinder>
           <radius>.1</radius>
           <length>.05</length>
         </cylinder>
       </geometry>
     </collision>
     <visual name="visual">
       <geometry>
         <cylinder>
           <radius>.1</radius>
           <length>.05</length>
         </cylinder>
       </geometry>
     </visual>
<!-- add a right wheel to the robot -->
   </link>
   <link name="right_wheel">
     <pose>0.0 -0.225 0.1 0 1.5707 1.5707</pose>
     <collision name="collision">
       <geometry>
         <cylinder>
           <radius>.1</radius>
           <length>.05</length>
         </cylinder>
       </geometry>
     </collision>
     <visual name="visual">
       <geometry>
         <cylinder>
           <radius>.1</radius>
           <length>.05</length>
         </cylinder>
       </geometry>
     </visual>
<!-- add two hinge joints for the left and right wheels`-->
   </link>
   <joint type="revolute" name="left_wheel_hinge">
     <pose>0 0 -0.03 0 0 0</pose>
     <child>left_wheel</child>
     <parent>chassis</parent>
     <axis>
       <xyz>0 1 0</xyz>
     </axis>
   </joint>

   <joint type="revolute" name="right_wheel_hinge">
     <pose>0 0 0.03 0 0 0</pose>
     <child>right_wheel</child>
     <parent>chassis</parent>
     <axis>
       <xyz>0 1 0</xyz>
     </axis>
   </joint>

    <include>
      <uri>model://hokuyo</uri>
      <pose>0.05 0 0.4 0 0 0</pose>
<!-- More info in gazebo add sensor to robot-->
    </include>
    <joint name="hokuyo_joint" type="fixed">
      <child>hokuyo::link</child>
      <parent>chassis</parent>
    </joint>

  </model>
</sdf>
